Workbook

Sheet Chamber_A
A1: Timestamp | B1: Temp_C | C1: Humidity (%) | D1: Note
A2: 45992 | B2: 5.12 | C2: 52.662631 | D2: sensor_check
A3: 45992.007 | B3: 4.85 | C3: 54.172094
A4: 45992.014 | B4: 5.82 | C4: 52.984181
A5: 45992.021 | B5: 6.16 | C5: 56.2205
A6: 45992.028 | B6: 5.25 | C6: 66.771936
A7: 45992.035 | B7: 5.75 | C7: 34.466732
A8: 45992.042 | B8: 6.56 | C8: 53.105198
A9: 45992.049 | B9: 6.6 | C9: 56.412099
A10: 45992.056 | B10: 6.93 | C10: 57.367952
A11: 45992.062 | B11: 6.79 | C11: 52.024683
A12: 45992.069 | B12: 7.66 | C12: 40.946226
A13: 45992.076 | B13: 7.77 | C13: 57.623964
A14: 45992.083 | B14: 7.63 | C14: 68.818802
... A18: 45992.111 | B18: 8.1 | C18: 54.509405
A19: 45992.118 | B19: 7.61 | C19: 46.576812 | D19: sensor_check
A20: 45992.125 | B20: 8.35 | C20: 52.324351
A21: 45992.132 | B21: 7.97 | C21: 65.400357
A22: 45992.139 | B22: 7.88 | C22: 59.661242
A23: 45992.146 | B23: 7.62 | C23: 68.858493
A24: 45992.153 | B24: 8.3 | C24: 64.419295
A25: 45992.16 | B25: 7.65 | C25: 58.512693
A26: 45992.167 | B26: 7.42 | C26: 68.951476
A27: 45992.174 | B27: 7.3 | C27: 58.511945
A28: 45992.181 | B28: 7.5 | C28: 61.623905
A29: 45992.188 | B29: 7.25 | C29: 52.627432
A30: 45992.194 | B30: 7.07 | C30: 55.532367
A31: 45992.201 | B31: 6.87 | C31: 49.420609
... A35: 45992.229 | B35: 5.42 | C35: 53.474792
A36: 45992.236 | B36: 5.74 | C36: 64.369977 | D36: sensor_check
A37: 45992.243 | B37: 5.68 | C37: 61.006952
A38: 45992.25 | B38: 4.92 | C38: 69.565169
A39: 45992.257 | B39: 4.37 | C39: 60.846198
A40: 45992.264 | B40: 4.12 | C40: 42.423678
A41: 45992.271 | B41: 4.45 | C41: 54.464375
A42: 45992.278 | B42: 4.24 | C42: 45.623942
A43: 45992.285 | B43: 3.92 | C43: 50.853761
A44: 45992.292 | B44: 3.2 | C44: 67.089827
A45: 45992.299 | B45: 3.34 | C45: 60.10027
A46: 45992.306 | B46: 3.09 | C46: 49.408557
...

Sheet Chamber_B_missing
A1: Timestamp | B1: Temperature (°C) | C1: Humidity (%) | D1: Note
A2: 45992 | B2: 25.8 | C2: 54.230569 | D2: sensor_check
A3: 45992.007 | B3: 25.75 | C3: 64.024151
A4: 45992.014 | B4: 24.85 | C4: 36.754097
A5: 45992.021 | B5: 25.22 | C5: 43.02689
A6: 45992.028 | B6: 23.55 | C6: 47.616908
A7: 45992.035 | B7: 24.31 | C7: 66.689431
A8: 45992.042 | B8: 24.82 | C8: 57.260696
A9: 45992.049 | B9: 24.36 | C9: 61.138538
A10: 45992.056 | B10: 25.43 | C10: 45.878713
A11: 45992.062 | B11: 26.2 | C11: 46.043713
A12: 45992.069 | C12: 58.58251
A13: 45992.076 | C13: 55.466195
A14: 45992.083 | B14: 25.14 | C14: 59.389911
A15: 45992.09 | B15: 25.97 | C15: 53.498632
A16: 45992.097 | B16: 24.27 | C16: 57.22515
A17: 45992.104 | B17: 25.15 | C17: 56.264953
A18: 45992.111 | B18: 26.09 | C18: 61.222139
A19: 45992.118 | B19: 24.01 | C19: 61.456066 | D19: sensor_check
A20: 45992.125 | B20: 24.23 | C20: 42.041024
A21: 45992.132 | B21: 24.75 | C21: 37.021852
A22: 45992.139 | B22: 24.69 | C22: 63.013963
A23: 45992.146 | B23: 25.49 | C23: 64.501801
A24: 45992.153 | B24: 25.14 | C24: 46.835016
A25: 45992.16 | B25: 23.94 | C25: 40.121317
A26: 45992.167 | B26: 25.31 | C26: 55.792279
A27: 45992.174 | B27: 24.65 | C27: 62.446706
A28: 45992.181 | B28: 25.76 | C28: 69.380756
A29: 45992.188 | B29: 24.62 | C29: 59.130381
A30: 45992.194 | B30: 24.62 | C30: 52.026266
A31: 45992.201 | B31: 25.32 | C31: 47.854955
... A35: 45992.229 | B35: 25.32 | C35: 71.390045
A36: 45992.236 | B36: 24.38 | C36: 69.281347 | D36: sensor_check
A37: 45992.243 | B37: 25.14 | C37: 64.088389
A38: 45992.25 | B38: 24.15 | C38: 47.633197
A39: 45992.257 | B39: 25.27 | C39: 61.840155
A40: 45992.264 | B40: 24.52 | C40: 60.117011
A41: 45992.271 | B41: 24.23 | C41: 58.540365
A42: 45992.278 | B42: 25.43 | C42: 64.997322
A43: 45992.285 | B43: 25.14 | C43: 60.082969
...

Sheet Chamber_C_mixed
A1: Timestamp | B1: temp reading | C1: Humidity (%) | D1: Note
A2: 45992 | B2: 7.65 | C2: 53.670737 | D2: sensor_check
A3: 45992.007 | B3: 8.42 | C3: 70.057399
A4: 45992.014 | B4: 7.33 | C4: 53.642242
A5: 45992.021 | B5: 7.8 | C5: 58.310339
A6: 45992.028 | B6: 7.71 | C6: 53.141845
A7: 45992.035 | B7: 8.7 | C7: 55.605706
A8: 45992.042 | B8: 8.14 | C8: 55.048133
A9: 45992.049 | B9: 7.5 | C9: 58.586593
A10: 45992.056 | B10: 8.36 | C10: 64.32246
A11: 45992.062 | B11: 8.03 | C11: 68.179152
A12: 45992.069 | B12: 7.05 | C12: 57.476961
A13: 45992.076 | B13: 7.02 | C13: 59.716375
A14: 45992.083 | B14: ERR | C14: 45.793084
A15: 45992.09 | B15: 7.89 | C15: 54.296986
A16: 45992.097 | B16: 7.95 | C16: 62.522316
A17: 45992.104 | B17: 7.99 | C17: 61.927749
A18: 45992.111 | B18: 8.11 | C18: 56.692878
A19: 45992.118 | B19: 8.47 | C19: 62.091152 | D19: sensor_check
A20: 45992.125 | B20: 7.44 | C20: 58.926134
A21: 45992.132 | B21: 7.41 | C21: 64.60245
A22: 45992.139 | B22: 7.45 | C22: 57.314873
A23: 45992.146 | B23: 8.14 | C23: 52.154413
A24: 45992.153 | B24: 8.62 | C24: 57.68673
A25: 45992.16 | B25: 7.78 | C25: 31.555245
A26: 45992.167 | B26: 6.75 | C26: 58.063086
A27: 45992.174 | C27: 25.812697
A28: 45992.181 | B28: 7.58 | C28: 41.212293
A29: 45992.188 | B29: 7.72 | C29: 58.614149
A30: 45992.194 | B30: 7.8 | C30: 58.820235
A31: 45992.201 | B31: 8.02 | C31: 45.70057
A32: 45992.208 | B32: 7.84 | C32: 49.303184
A33: 45992.215 | B33: 8.52 | C33: 65.964328
A34: 45992.222 | B34: 7.66 | C34: 51.127759
A35: 45992.229 | B35: 7.57 | C35: 72.943362
A36: 45992.236 | B36: 8.24 | C36: 54.984641 | D36: sensor_check
A37: 45992.243 | B37: 7.23 | C37: 58.264289
A38: 45992.25 | B38: 8.19 | C38: 67.934995
A39: 45992.257 | B39: 8.05 | C39: 56.048217
A40: 45992.264 | B40: 7.93 | C40: 46.981248
...

Sheet No_Temp_Column
A1: Timestamp | B1: Pressure (bar) | C1: Comment
A2: 45992 | B2: 1.0187193 | C2: ok
A3: 45992.021 | B3: 1.0315991 | C3: ok
A4: 45992.042 | B4: 0.92978655 | C4: ok
A5: 45992.062 | B5: 1.016552 | C5: ok
A6: 45992.083 | B6: 0.98486901 | C6: ok
A7: 45992.104 | B7: 0.97586049 | C7: ok
A8: 45992.125 | B8: 1.0435278 | C8: ok
A9: 45992.146 | B9: 1.0739637 | C9: ok
A10: 45992.167 | B10: 1.0897185 | C10: ok
A11: 45992.188 | B11: 1.0657404 | C11: ok
A12: 45992.208 | B12: 0.99451329 | C12: ok
A13: 45992.229 | B13: 1.017636 | C13: ok
... A21: 45992.396 | B21: 1.0316955 | C21: ok

Sheet Empty_Temps
A1: Timestamp | B1: TEMP | C1: Humidity (%) | D1: Note
A2: 45992 | C2: 55.023946 | D2: sensor_check
A3: 45992.007 | C3: 57.72168
A4: 45992.014 | C4: 60.360634
A5: 45992.021 | C5: 52.001268
A6: 45992.028 | C6: 61.049985
A7: 45992.035 | C7: 58.030741
A8: 45992.042 | C8: 45.121495
A9: 45992.049 | C9: 66.538438
A10: 45992.056 | C10: 50.994042
A11: 45992.062 | C11: 41.759237
A12: 45992.069 | C12: 46.63965
A13: 45992.076 | C13: 46.831639
A14: 45992.083 | C14: 55.417387
... A18: 45992.111 | C18: 57.719003
A19: 45992.118 | C19: 57.528383 | D19: sensor_check
A20: 45992.125 | C20: 58.278628
A21: 45992.132 | C21: 59.929077
A22: 45992.139 | C22: 38.136373
A23: 45992.146 | C23: 52.084494
A24: 45992.153 | C24: 37.558319
A25: 45992.16 | C25: 55.288479
A26: 45992.167 | C26: 54.962936
A27: 45992.174 | C27: 63.364258
A28: 45992.181 | C28: 64.501075
A29: 45992.188 | C29: 56.6222
A30: 45992.194 | C30: 50.997111
A31: 45992.201 | C31: 58.881289

Sheet Independent_Check
A1: Independent Excel Verification (Chamber_A)
A3: Instructions | E3: Expected results for dataset (script cleaning rules)
A4: This sheet independently computes MKT using Excel formulas from the copied Chamber_A data. | E4: Sheet | F4: Temperature column | G4: No. of points | H4: MKT (K) | I4: MKT (°C)
A5: Acceptance: Script MKT(°C) matches this sheet's MKT(°C) within ±0.01 °C (rounding). | E5: Chamber_A | F5: Temp_C | G5: 288 | H5: 278.41 | I5: 5.26
E6: Chamber_B_missing | F6: Temperature (°C) | G6: 140 | H6: 298.11 | I6: 24.96
A7: Row-by-row terms | E7: Chamber_C_mixed | F7: temp reading | G7: 58 | H7: 281.08 | I7: 7.93
A8: Temp (°C) | B8: Temp (K) | C8: exp(-Ea/(R*T))
A9: =Chamber_A!B2 | B9: =A9+273.15 | C9: =EXP(-83144/(8.314*B9))
A10: =Chamber_A!B3 | B10: =A10+273.15 | C10: =EXP(-83144/(8.314*B10))
A11: =Chamber_A!B4 | B11: =A11+273.15 | C11: =EXP(-83144/(8.314*B11))
A12: =Chamber_A!B5 | B12: =A12+273.15 | C12: =EXP(-83144/(8.314*B12))
A13: =Chamber_A!B6 | B13: =A13+273.15 | C13: =EXP(-83144/(8.314*B13))
A14: =Chamber_A!B7 | B14: =A14+273.15 | C14: =EXP(-83144/(8.314*B14))
A15: =Chamber_A!B8 | B15: =A15+273.15 | C15: =EXP(-83144/(8.314*B15))
A16: =Chamber_A!B9 | B16: =A16+273.15 | C16: =EXP(-83144/(8.314*B16))
A17: =Chamber_A!B10 | B17: =A17+273.15 | C17: =EXP(-83144/(8.314*B17))
A18: =Chamber_A!B11 | B18: =A18+273.15 | C18: =EXP(-83144/(8.314*B18))
A19: =Chamber_A!B12 | B19: =A19+273.15 | C19: =EXP(-83144/(8.314*B19))
A20: =Chamber_A!B13 | B20: =A20+273.15 | C20: =EXP(-83144/(8.314*B20))
... A296: =Chamber_A!B289 | B296: =A296+273.15 | C296: =EXP(-83144/(8.314*B296))
A298: n (valid points) | B298: =COUNT(A9:A296)
A299: Average exp term | B299: =AVERAGE(C9:C296)
A300: MKT (K) | B300: =-83144/(8.314*LN(B299))
A301: MKT (°C) | B301: =B300-273.15
